<?xml version="1.0"?>
<robot xmlns:xacro="http://www.ros.org/wiki/xacro">

  <!-- Wheel macro -->
  <xacro:macro name="wheel" params="prefix y_offset">

    <link name="${prefix}_wheel">
      <visual>
        <geometry>
          <cylinder radius="${wheel_radius}" length="${wheel_width}"/>
        </geometry>
        <origin xyz="0 0 0" rpy="${pi/2} 0 0"/>
        <material name="black"/>
      </visual>
      <collision>
        <geometry>
          <cylinder radius="${wheel_radius}" length="${wheel_width}"/>
        </geometry>
        <origin xyz="0 0 0" rpy="${pi/2} 0 0"/>
      </collision>
      <inertial>
        <mass value="${wheel_mass}"/>
        <origin xyz="0 0 0" rpy="${pi/2} 0 0"/>
        <xacro:cylinder_inertia m="${wheel_mass}" r="${wheel_radius}" h="${wheel_width}"/>
      </inertial>
    </link>

    <joint name="${prefix}_wheel_joint" type="continuous">
      <parent link="base_link"/>
      <child link="${prefix}_wheel"/>
      <origin xyz="0 ${y_offset} ${-base_height/2}" rpy="0 0 0"/>
      <axis xyz="0 1 0"/>
      <dynamics damping="0.1" friction="0.1"/>
    </joint>

    <!-- Gazebo properties for wheel -->
    <gazebo reference="${prefix}_wheel">
      <material>Gazebo/Black</material>
      <mu1>1.0</mu1>
      <mu2>1.0</mu2>
      <kp>1000000.0</kp>
      <kd>100.0</kd>
    </gazebo>

  </xacro:macro>

</robot>
